[2025-01-20T11:56:47.307+0000] {local_task_job_runner.py:123} INFO - ::group::Pre task execution logs
[2025-01-20T11:56:47.319+0000] {taskinstance.py:2613} INFO - Dependencies all met for dep_context=non-requeueable deps ti=<TaskInstance: dag_cr_table_snowflake.insert_data_query manual__2025-01-20T11:51:37.298308+00:00 [queued]>
[2025-01-20T11:56:47.324+0000] {taskinstance.py:2613} INFO - Dependencies all met for dep_context=requeueable deps ti=<TaskInstance: dag_cr_table_snowflake.insert_data_query manual__2025-01-20T11:51:37.298308+00:00 [queued]>
[2025-01-20T11:56:47.324+0000] {taskinstance.py:2866} INFO - Starting attempt 2 of 2
[2025-01-20T11:56:47.334+0000] {taskinstance.py:2889} INFO - Executing <Task(SnowflakeOperator): insert_data_query> on 2025-01-20 11:51:37.298308+00:00
[2025-01-20T11:56:47.342+0000] {warnings.py:112} WARNING - /home/***/.local/lib/python3.12/site-packages/***/task/task_runner/standard_task_runner.py:70: DeprecationWarning: This process (pid=1294) is multi-threaded, use of fork() may lead to deadlocks in the child.
  pid = os.fork()

[2025-01-20T11:56:47.345+0000] {standard_task_runner.py:72} INFO - Started process 1296 to run task
[2025-01-20T11:56:47.345+0000] {standard_task_runner.py:104} INFO - Running: ['***', 'tasks', 'run', 'dag_cr_table_snowflake', 'insert_data_query', 'manual__2025-01-20T11:51:37.298308+00:00', '--job-id', '9', '--raw', '--subdir', 'DAGS_FOLDER/dag_create_table.py', '--cfg-path', '/tmp/tmpxyvs_m0t']
[2025-01-20T11:56:47.350+0000] {standard_task_runner.py:105} INFO - Job 9: Subtask insert_data_query
[2025-01-20T11:56:47.408+0000] {task_command.py:467} INFO - Running <TaskInstance: dag_cr_table_snowflake.insert_data_query manual__2025-01-20T11:51:37.298308+00:00 [running]> on host fd6029332267
[2025-01-20T11:56:47.472+0000] {taskinstance.py:3132} INFO - Exporting env vars: AIRFLOW_CTX_DAG_OWNER='***' AIRFLOW_CTX_DAG_ID='dag_cr_table_snowflake' AIRFLOW_CTX_TASK_ID='insert_data_query' AIRFLOW_CTX_EXECUTION_DATE='2025-01-20T11:51:37.298308+00:00' AIRFLOW_CTX_TRY_NUMBER='2' AIRFLOW_CTX_DAG_RUN_ID='manual__2025-01-20T11:51:37.298308+00:00'
[2025-01-20T11:56:47.473+0000] {taskinstance.py:731} INFO - ::endgroup::
[2025-01-20T11:56:47.475+0000] {sql.py:278} INFO - Executing: INSERT INTO employees (1,'Adi Nusa','Back End Developer');
INSERT INTO employees (2,'Helmi','Front End Developer');
INSERT INTO employees (3,'Febri','Android Developer');
INSERT INTO employees (4,'Doni','IOS Developer');
INSERT INTO employees (5,'Firda','IoT Developer');
[2025-01-20T11:56:47.521+0000] {base.py:84} INFO - Retrieving connection 'snowflake_conn'
[2025-01-20T11:56:47.544+0000] {base.py:84} INFO - Retrieving connection 'snowflake_conn'
[2025-01-20T11:56:47.546+0000] {connection.py:414} INFO - Snowflake Connector for Python Version: 3.12.4, Python Version: 3.12.8, Platform: Linux-6.12.9-orbstack-00297-gaa9b46293ea3-aarch64-with-glibc2.36
[2025-01-20T11:56:47.547+0000] {connection.py:1197} INFO - Connecting to GLOBAL Snowflake domain
[2025-01-20T11:56:47.547+0000] {connection.py:1278} INFO - This connection is in OCSP Fail Open Mode. TLS Certificates would be checked for validity and revocation status. Any other Certificate Revocation related exceptions or OCSP Responder failures would be disregarded in favor of connectivity.
[2025-01-20T11:56:48.214+0000] {cursor.py:1166} INFO - Number of results in first chunk: 1
[2025-01-20T11:56:48.215+0000] {sql.py:553} INFO - Running statement: INSERT INTO employees (1,'Adi Nusa','Back End Developer');, parameters: None
[2025-01-20T11:56:48.327+0000] {connection.py:789} INFO - closed
[2025-01-20T11:56:48.357+0000] {connection.py:795} INFO - No async queries seem to be running, deleting session
[2025-01-20T11:56:48.401+0000] {taskinstance.py:3311} ERROR - Task failed with exception
Traceback (most recent call last):
  File "/home/airflow/.local/lib/python3.12/site-packages/airflow/models/taskinstance.py", line 767, in _execute_task
    result = _execute_callable(context=context, **execute_callable_kwargs)
             ^^^^^^^^^^^^^^^^^^^^^^^^^^^^^^^^^^^^^^^^^^^^^^^^^^^^^^^^^^^^^
  File "/home/airflow/.local/lib/python3.12/site-packages/airflow/models/taskinstance.py", line 733, in _execute_callable
    return ExecutionCallableRunner(
           ^^^^^^^^^^^^^^^^^^^^^^^^
  File "/home/airflow/.local/lib/python3.12/site-packages/airflow/utils/operator_helpers.py", line 252, in run
    return self.func(*args, **kwargs)
           ^^^^^^^^^^^^^^^^^^^^^^^^^^
  File "/home/airflow/.local/lib/python3.12/site-packages/airflow/models/baseoperator.py", line 422, in wrapper
    return func(self, *args, **kwargs)
           ^^^^^^^^^^^^^^^^^^^^^^^^^^^
  File "/home/airflow/.local/lib/python3.12/site-packages/airflow/providers/common/sql/operators/sql.py", line 284, in execute
    output = hook.run(
             ^^^^^^^^^
  File "/home/airflow/.local/lib/python3.12/site-packages/airflow/providers/snowflake/hooks/snowflake.py", line 435, in run
    self._run_command(cur, sql_statement, parameters)  # type: ignore[attr-defined]
    ^^^^^^^^^^^^^^^^^^^^^^^^^^^^^^^^^^^^^^^^^^^^^^^^^
  File "/home/airflow/.local/lib/python3.12/site-packages/airflow/providers/common/sql/hooks/sql.py", line 558, in _run_command
    cur.execute(sql_statement)
  File "/home/airflow/.local/lib/python3.12/site-packages/snowflake/connector/cursor.py", line 1097, in execute
    Error.errorhandler_wrapper(self.connection, self, error_class, errvalue)
  File "/home/airflow/.local/lib/python3.12/site-packages/snowflake/connector/errors.py", line 284, in errorhandler_wrapper
    handed_over = Error.hand_to_other_handler(
                  ^^^^^^^^^^^^^^^^^^^^^^^^^^^^
  File "/home/airflow/.local/lib/python3.12/site-packages/snowflake/connector/errors.py", line 339, in hand_to_other_handler
    cursor.errorhandler(connection, cursor, error_class, error_value)
  File "/home/airflow/.local/lib/python3.12/site-packages/snowflake/connector/errors.py", line 215, in default_errorhandler
    raise error_class(
snowflake.connector.errors.ProgrammingError: 001003 (42000): 01b9d64c-3201-63d5-000b-894e0001b1ba: SQL compilation error:
syntax error line 1 at position 23 unexpected '1'.
[2025-01-20T11:56:48.412+0000] {taskinstance.py:1225} INFO - Marking task as FAILED. dag_id=dag_cr_table_snowflake, task_id=insert_data_query, run_id=manual__2025-01-20T11:51:37.298308+00:00, execution_date=20250120T115137, start_date=20250120T115647, end_date=20250120T115648
[2025-01-20T11:56:48.423+0000] {taskinstance.py:340} INFO - ::group::Post task execution logs
[2025-01-20T11:56:48.424+0000] {standard_task_runner.py:124} ERROR - Failed to execute job 9 for task insert_data_query (001003 (42000): 01b9d64c-3201-63d5-000b-894e0001b1ba: SQL compilation error:
syntax error line 1 at position 23 unexpected '1'.; 1296)
Traceback (most recent call last):
  File "/home/airflow/.local/lib/python3.12/site-packages/airflow/task/task_runner/standard_task_runner.py", line 117, in _start_by_fork
    ret = args.func(args, dag=self.dag)
          ^^^^^^^^^^^^^^^^^^^^^^^^^^^^^
  File "/home/airflow/.local/lib/python3.12/site-packages/airflow/cli/cli_config.py", line 49, in command
    return func(*args, **kwargs)
           ^^^^^^^^^^^^^^^^^^^^^
  File "/home/airflow/.local/lib/python3.12/site-packages/airflow/utils/cli.py", line 116, in wrapper
    return f(*args, **kwargs)
           ^^^^^^^^^^^^^^^^^^
  File "/home/airflow/.local/lib/python3.12/site-packages/airflow/cli/commands/task_command.py", line 483, in task_run
    task_return_code = _run_task_by_selected_method(args, _dag, ti)
                       ^^^^^^^^^^^^^^^^^^^^^^^^^^^^^^^^^^^^^^^^^^^^
  File "/home/airflow/.local/lib/python3.12/site-packages/airflow/cli/commands/task_command.py", line 256, in _run_task_by_selected_method
    return _run_raw_task(args, ti)
           ^^^^^^^^^^^^^^^^^^^^^^^
  File "/home/airflow/.local/lib/python3.12/site-packages/airflow/cli/commands/task_command.py", line 341, in _run_raw_task
    return ti._run_raw_task(
           ^^^^^^^^^^^^^^^^^
  File "/home/airflow/.local/lib/python3.12/site-packages/airflow/utils/session.py", line 97, in wrapper
    return func(*args, session=session, **kwargs)
           ^^^^^^^^^^^^^^^^^^^^^^^^^^^^^^^^^^^^^^
  File "/home/airflow/.local/lib/python3.12/site-packages/airflow/models/taskinstance.py", line 3005, in _run_raw_task
    return _run_raw_task(
           ^^^^^^^^^^^^^^
  File "/home/airflow/.local/lib/python3.12/site-packages/airflow/models/taskinstance.py", line 273, in _run_raw_task
    TaskInstance._execute_task_with_callbacks(
  File "/home/airflow/.local/lib/python3.12/site-packages/airflow/models/taskinstance.py", line 3159, in _execute_task_with_callbacks
    result = self._execute_task(context, task_orig)
             ^^^^^^^^^^^^^^^^^^^^^^^^^^^^^^^^^^^^^^
  File "/home/airflow/.local/lib/python3.12/site-packages/airflow/models/taskinstance.py", line 3183, in _execute_task
    return _execute_task(self, context, task_orig)
           ^^^^^^^^^^^^^^^^^^^^^^^^^^^^^^^^^^^^^^^
  File "/home/airflow/.local/lib/python3.12/site-packages/airflow/models/taskinstance.py", line 767, in _execute_task
    result = _execute_callable(context=context, **execute_callable_kwargs)
             ^^^^^^^^^^^^^^^^^^^^^^^^^^^^^^^^^^^^^^^^^^^^^^^^^^^^^^^^^^^^^
  File "/home/airflow/.local/lib/python3.12/site-packages/airflow/models/taskinstance.py", line 733, in _execute_callable
    return ExecutionCallableRunner(
           ^^^^^^^^^^^^^^^^^^^^^^^^
  File "/home/airflow/.local/lib/python3.12/site-packages/airflow/utils/operator_helpers.py", line 252, in run
    return self.func(*args, **kwargs)
           ^^^^^^^^^^^^^^^^^^^^^^^^^^
  File "/home/airflow/.local/lib/python3.12/site-packages/airflow/models/baseoperator.py", line 422, in wrapper
    return func(self, *args, **kwargs)
           ^^^^^^^^^^^^^^^^^^^^^^^^^^^
  File "/home/airflow/.local/lib/python3.12/site-packages/airflow/providers/common/sql/operators/sql.py", line 284, in execute
    output = hook.run(
             ^^^^^^^^^
  File "/home/airflow/.local/lib/python3.12/site-packages/airflow/providers/snowflake/hooks/snowflake.py", line 435, in run
    self._run_command(cur, sql_statement, parameters)  # type: ignore[attr-defined]
    ^^^^^^^^^^^^^^^^^^^^^^^^^^^^^^^^^^^^^^^^^^^^^^^^^
  File "/home/airflow/.local/lib/python3.12/site-packages/airflow/providers/common/sql/hooks/sql.py", line 558, in _run_command
    cur.execute(sql_statement)
  File "/home/airflow/.local/lib/python3.12/site-packages/snowflake/connector/cursor.py", line 1097, in execute
    Error.errorhandler_wrapper(self.connection, self, error_class, errvalue)
  File "/home/airflow/.local/lib/python3.12/site-packages/snowflake/connector/errors.py", line 284, in errorhandler_wrapper
    handed_over = Error.hand_to_other_handler(
                  ^^^^^^^^^^^^^^^^^^^^^^^^^^^^
  File "/home/airflow/.local/lib/python3.12/site-packages/snowflake/connector/errors.py", line 339, in hand_to_other_handler
    cursor.errorhandler(connection, cursor, error_class, error_value)
  File "/home/airflow/.local/lib/python3.12/site-packages/snowflake/connector/errors.py", line 215, in default_errorhandler
    raise error_class(
snowflake.connector.errors.ProgrammingError: 001003 (42000): 01b9d64c-3201-63d5-000b-894e0001b1ba: SQL compilation error:
syntax error line 1 at position 23 unexpected '1'.
[2025-01-20T11:56:48.440+0000] {local_task_job_runner.py:266} INFO - Task exited with return code 1
[2025-01-20T11:56:48.457+0000] {taskinstance.py:3895} INFO - 0 downstream tasks scheduled from follow-on schedule check
[2025-01-20T11:56:48.463+0000] {local_task_job_runner.py:245} INFO - ::endgroup::
